Workbook

Sheet Задание
A1: ЗАДАНИЕ на семинар
A3: 1 | B3: Дать оценку сведений о добыче нефти в РФ, 2008-2019 гг.
A4: 1.1 | B4: Распределение добычи нефти по категориям производителей, по годам
B5: перевести в млн. баррелей
B6: перевести в млн. б.н.э
B7: осуществить сопоставление в абсолютном выражении
B8: по годам (цепные)
B9: сравнение с ВИНК
B10: осуществить сопоставление в относительном выражении
B11: по годам (ОВД: цепной, 2010=0)
B12: между категориями производителей (ОВС, ОВК)
A13: 1.2 | B13: Распределение добычи нефти по регионам, по годам
B14: осуществить сопоставление в абсолютном выражении
B15: по годам
B16: сравнение с Европейской частью
B17: осуществить сопоставление в относительном выражении
B18: по годам (ОВД: цепной, 2014=0)
B19: между регионами (ОВС, ОВК)
A20: 1.3 | B20: Добыча нефти по новым источникам добычи, по годам
A21: 1.4 | B21: Основные сведения о фонде скважин, осуществляющих добычу нефти, по годам
A22: 1.5 | B22: Запасы углеводородов (доказанные) на 30.12.2019 и 30.12.2020, млн. б.н.э
B23: минимум 10 компаний
B24: осуществить сопоставление в абсолютном выражении
B25: сравнение с одной из ВИНК (на выбор студента с учетом обоснования)
B26: осуществить сопоставление в относительном выражении
B27: между компаниями (какая относительная величина)?
B28: относительно запасов нефти в РФ (какая относительная величина)?
A29: 1.6 | B29: Международное сопоставление по суммарным уровням добычи нефти
B30: осуществить международной сопоставление по суммарным уровням добычи нефти (минимум 10 стран, в том числе РФ)
A31: 1.7 | B31: Данные по категориям производителей нефти по итогам 2018 года
A32: 1.8 | B32: Данные по нефтегазовым компаниям по итогам 2018 года
B34: Построить таблицы (MS Excel)
B35: Подготовить аналитическую записку о добыче нефти в РФ на основе представленных данных – Сделать выводы (MS Word)

Sheet 1.1
A1: Распределение добычи нефти по категориям производителей, по годам, млн. т
A3: Показатель | C3: 2008 | D3: 2009 | E3: 2010 | F3: 2011 | G3: 2012 | H3: 2013 | I3: 2014 | J3: 2015 | K3: 2016 | L3: 2017 | M3: 2018 | N3: 2019 | O3: Среднее значение за 2008-2019 годы | P3: Xмин | Q3: Хмакс | R3: Размах вариации, R | S3: Медиана, Ме | T3: Q1 | U3: Q3 | V3: Межквартильный размах, IQR | W3: Среднее линйеное (абсолютное) отклонение, L | X3: Дисперсия | Y3: Среднеквадратическое отклонение, СКО | Z3: Коэффициент осциляции (VR), % | AA3: Коэффициент линейного отклонения (VL), % | AB3: Коэффициент вариации (V), %
A4: А | B4: Б | C4: 1 | D4: 2 | E4: 3 | F4: 4 | G4: 5 | H4: 6 | I4: 7 | J4: 8 | K4: 9 | L4: 10 | M4: 11 | N4: 12 | O4: 13 | P4: 14 | Q4: 15 | R4: 16 | S4: 17 | T4: 18 | U4: 19 | V4: 20 | W4: 21 | X4: 22 | Y4: 23 | Z4: 24 | AA4: 25 | AB4: 26
A5: Добыча нефти (всего) | B5: 1 | C5: 488.6 | D5: 494.3 | E5: 505.2 | F5: 511.4 | G5: 518.1 | H5: 523.4 | I5: 526.8 | J5: 534.3 | K5: 547.6 | L5: 546.8 | M5: 556 | N5: 561.2 | O5: =AVERAGE(C5:N5) -> 526.14167 | P5: =QUARTILE(C5:N5,0) -> 488.6 | Q5: =QUARTILE(C5:N5, 4) -> 561.2 | R5: =Q5-P5 -> 72.6 | S5: =QUARTILE(C5:N5,2) -> 525.1 | T5: =QUARTILE(C5:N5,1) -> 509.85 | U5: =QUARTILE(C5:N5,3) -> 547 | V5: 525,1 (Q1-Q3: 509,9-547,0) | W5: =SUM(E15:E26)/COUNTA(C5:N5) -> 19.308333 | X5: =SUM(F15:F26)/COUNTA(C5:N5) -> 518.84576 | Y5: =SQRT(X5) -> 22.778186 | Z5: =R5/O5*100 -> 13.798565 | AA5: =W5/O5*100 -> 3.6697974 | AB5: =Y5/O5*100 -> 4.3292876
A6: Добыча нефти ВИНК (включая ПАО ГАЗПРОМ) | B6: 2 | C6: 436.4 | D6: 439.4 | E6: 450.7 | F6: 453.9 | G6: 460.4 | H6: 464.4 | I6: 464.5 | J6: 464.8 | K6: 472.3 | L6: 468.6 | M6: 473.7 | N6: 475.5 | O6: =AVERAGE(C6:N6) -> 460.38333 | P6: =QUARTILE(C6:N6,0) -> 436.4 | Q6: =QUARTILE(C6:N6, 4) -> 475.5 | R6: =Q6-P6 -> 39.1 | S6: =QUARTILE(C6:N6,2) -> 464.45 | T6: =QUARTILE(C6:N6,1) -> 453.1 | U6: =QUARTILE(C6:N6,3) -> 469.525 | V6: 464,5 (Q1-Q3: 453,1-469,5) | W6: =SUM(E35:E46)/COUNTA(C6:N6) -> 10.188889 | X6: =SUM(F35:F46)/COUNTA(C6:N6) -> 151.60472 | Y6: =SQRT(X6) -> 12.312787 | Z6: =R6/O6*100 -> 8.4929226 | AA6: =W6/O6*100 -> 2.2131316 | AB6: =Y6/O6*100 -> 2.6744641
A7: Добыча нефти независимыми производителями | B7: 3 | C7: 40.2 | D7: 40.1 | E7: 40.1 | F7: 42.4 | G7: 43.5 | H7: 45.1 | I7: 47.9 | J7: 54.6 | K7: 59.3 | L7: 61.7 | M7: 63.5 | N7: 66.2 | O7: =AVERAGE(C7:N7) -> 50.383333 | P7: =QUARTILE(C7:N7,0) -> 40.1 | Q7: =QUARTILE(C7:N7, 4) -> 66.2 | R7: =Q7-P7 -> 26.1 | S7: =QUARTILE(C7:N7,2) -> 46.5 | T7: =QUARTILE(C7:N7,1) -> 41.85 | U7: =QUARTILE(C7:N7,3) -> 59.9 | V7: 46,5 (Q1-Q3: 41,9-59,9) | W7: =SUM(E55:E66)/COUNTA(C7:N7) -> 8.8972222 | X7: =SUM(F55:F66)/COUNTA(C7:N7) -> 92.329722 | Y7: =SQRT(X7) -> 9.6088356 | Z7: =R7/O7*100 -> 51.802845 | AA7: =W7/O7*100 -> 17.659058 | AB7: =Y7/O7*100 -> 19.071457
A8: Добыча нефти операторами СРП | B8: 4 | C8: 12 | D8: 14.8 | E8: 14.4 | F8: 15.1 | G8: 14.1 | H8: 14 | I8: 14.4 | J8: 15 | K8: 16 | L8: 16.5 | M8: 18.7 | N8: 19.4 | O8: =AVERAGE(C8:N8) -> 15.366667 | P8: =QUARTILE(C8:N8,0) -> 12 | Q8: =QUARTILE(C8:N8, 4) -> 19.4 | R8: =Q8-P8 -> 7.4 | S8: =QUARTILE(C8:N8,2) -> 14.9 | T8: =QUARTILE(C8:N8,1) -> 14.325 | U8: =QUARTILE(C8:N8,3) -> 16.125 | V8: 14,9 (Q1-Q3: 14,3-16,1) | W8: =SUM(E75:E86)/COUNTA(C8:N8) -> 1.5222222 | X8: =SUM(F75:F86)/COUNTA(C8:N8) -> 3.8555556 | Y8: =SQRT(X8) -> 1.9635569 | Z8: =R8/O8*100 -> 48.156182 | AA8: =W8/O8*100 -> 9.9060014 | AB8: =Y8/O8*100 -> 12.778027
A10: Источник: данные ЦДУ ТЭК.
A12: Расчетные значения добычи нефти (всего), млн.т
A13: Показатель | C13: Добыча нефти | D13: Х-Хср | E13: |Х-Хср| | F13: (Х-Хср)2 | G13: Сравнение с предущим периодом, % | H13: Х1-Хср | I13: |Х1-Хср| | J13: (Х1-Хср)2
A14: А | B14: Б | C14: В | D14: 1 | E14: 2 | F14: 3 | G14: 4 | H14: 5 | I14: 6 | J14: 7
A15: {=TRANSPOSE(C3:N3)} -> 2008 | B15: 1 | C15: {=TRANSPOSE(C5:N5)} -> 488.6 | D15: =C15-$C$27 -> -37.541667 | E15: =ABS(D15) -> 37.541667 | F15: =POWER(D15, 2) -> 1409.3767 | G15: - | H15: - | I15: - | J15: -
A16: 2009 | B16: 2 | C16: 494.3 | D16: =C16-$C$27 -> -31.841667 | E16: =ABS(D16) -> 31.841667 | F16: =POWER(D16, 2) -> 1013.8917 | G16: =(C16/C15)*100 -> 101.1666 | H16: =G16-$G$27 -> -0.10075793 | I16: =ABS(H16) -> 0.10075793 | J16: =POWER(I16, 2) -> 0.010152161
A17: 2010 | B17: 3 | C17: 505.2 | D17: =C17-$C$27 -> -20.941667 | E17: =ABS(D17) -> 20.941667 | F17: =POWER(D17, 2) -> 438.5534 | G17: =(C17/C16)*100 -> 102.20514 | H17: =G17-$G$27 -> 0.9377822 | I17: =ABS(H17) -> 0.9377822 | J17: =POWER(I17, 2) -> 0.87943546
A18: 2011 | B18: 4 | C18: 511.4 | D18: =C18-$C$27 -> -14.741667 | E18: =ABS(D18) -> 14.741667 | F18: =POWER(D18, 2) -> 217.31674 | G18: =(C18/C17)*100 -> 101.22724 | H18: =G18-$G$27 -> -0.040119639 | I18: =ABS(H18) -> 0.040119639 | J18: =POWER(I18, 2) -> 0.0016095854
A19: 2012 | B19: 5 | C19: 518.1 | D19: =C19-$C$27 -> -8.0416667 | E19: =ABS(D19) -> 8.0416667 | F19: =POWER(D19, 2) -> 64.668403 | G19: =(C19/C18)*100 -> 101.31013 | H19: =G19-$G$27 -> 0.042772681 | I19: =ABS(H19) -> 0.042772681 | J19: =POWER(I19, 2) -> 0.0018295022
A20: 2013 | B20: 6 | C20: 523.4 | D20: =C20-$C$27 -> -2.7416667 | E20: =ABS(D20) -> 2.7416667 | F20: =POWER(D20, 2) -> 7.5167361 | G20: =(C20/C19)*100 -> 101.02297 | H20: =G20-$G$27 -> -0.24438784 | I20: =ABS(H20) -> 0.24438784 | J20: =POWER(I20, 2) -> 0.059725415
A21: 2014 | B21: 7 | C21: 526.8 | D21: =C21-$C$27 -> 0.65833333 | E21: =ABS(D21) -> 0.65833333 | F21: =POWER(D21, 2) -> 0.43340278 | G21: =(C21/C20)*100 -> 100.6496 | H21: =G21-$G$27 -> -0.6177576 | I21: =ABS(H21) -> 0.6177576 | J21: =POWER(I21, 2) -> 0.38162445
A22: 2015 | B22: 8 | C22: 534.3 | D22: =C22-$C$27 -> 8.1583333 | E22: =ABS(D22) -> 8.1583333 | F22: =POWER(D22, 2) -> 66.558403 | G22: =(C22/C21)*100 -> 101.42369 | H22: =G22-$G$27 -> 0.15633383 | I22: =ABS(H22) -> 0.15633383 | J22: =POWER(I22, 2) -> 0.024440266
A23: 2016 | B23: 9 | C23: 547.6 | D23: =C23-$C$27 -> 21.458333 | E23: =ABS(D23) -> 21.458333 | F23: =POWER(D23, 2) -> 460.46007 | G23: =(C23/C22)*100 -> 102.48924 | H23: =G23-$G$27 -> 1.2218819 | I23: =ABS(H23) -> 1.2218819 | J23: =POWER(I23, 2) -> 1.4929953
A24: 2017 | B24: 10 | C24: 546.8 | D24: =C24-$C$27 -> 20.658333 | E24: =ABS(D24) -> 20.658333 | F24: =POWER(D24, 2) -> 426.76674 | G24: =(C24/C23)*100 -> 99.853908 | H24: =G24-$G$27 -> -1.4134484 | I24: =ABS(H24) -> 1.4134484 | J24: =POWER(I24, 2) -> 1.9978364
A25: 2018 | B25: 11 | C25: 556 | D25: =C25-$C$27 -> 29.858333 | E25: =ABS(D25) -> 29.858333 | F25: =POWER(D25, 2) -> 891.52007 | G25: =(C25/C24)*100 -> 101.68252 | H25: =G25-$G$27 -> 0.41516008 | I25: =ABS(H25) -> 0.41516008 | J25: =POWER(I25, 2) -> 0.17235789
A26: 2019 | B26: 12 | C26: 561.2 | D26: =C26-$C$27 -> 35.058333 | E26: =ABS(D26) -> 35.058333 | F26: =POWER(D26, 2) -> 1229.0867 | G26: =(C26/C25)*100 -> 100.93525 | H26: =G26-$G$27 -> -0.33210458 | I26: =ABS(H26) -> 0.33210458 | J26: =POWER(I26, 2) -> 0.11029345
A27: Среднее значение | B27: 13 | C27: =AVERAGE(C15:C26) -> 526.14167 | D27: - | E27: - | F27: - | G27: =POWER(PRODUCT(G16:G26), 1/COUNTA(G16:G26)) -> 101.26736 | H27: - | I27: - | J27: -
A29: Источник: расчет автора на основе данных ЦДУ ТЭК.
A32: Расчетные значения добычи нефти ВИНК (включая ПАО ГАЗПРОМ), млн.т
A33: Показатель | C33: Добыча нефти | D33: Х-Хср | E33: |Х-Хср| | F33: (Х-Хср)2 | G33: Сравнение с предущим периодом, % | H33: Х1-Хср, % | I33: |Х1-Хср|, % | J33: (Х1-Хср)2, % | K33: Удельный вес в общем объёме, % | L33: Х-Хср, % | M33: |Х-Хср|, % | N33: (Х-Хср)2, %
A34: А | B34: Б | C34: В | D34: 1 | E34: 2 | F34: 3 | G34: 4 | H34: 5 | I34: 6 | J34: 7 | K34: 8 | L34: 1 | M34: 2 | N34: 3
A35: {=TRANSPOSE(C3:N3)} -> 2008 | B35: 1 | C35: {=TRANSPOSE(C6:N6)} -> 436.4 | D35: =C35-$C$47 -> -23.983333 | E35: =ABS(D35) -> 23.983333 | F35: =POWER(D35, 2) -> 575.20028 | G35: - | H35: - | I35: - | J35: - | K35: =C35/C15*100 -> 89.316414 | L35: =K35-$K$47 -> 1.7489185 | M35: =ABS(L35) -> 1.7489185 | N35: =POWER(L35, 2) -> 3.058716
A36: 2009 | B36: 2 | C36: 439.4 | D36: =C36-$C$47 -> -20.983333 | E36: =ABS(D36) -> 20.983333 | F36: =POWER(D36, 2) -> 440.30028 | G36: =(C36/C35)*100 -> 100.68744 | H36: =G36-$G$47 -> -0.0956771 | I36: =ABS(H36) -> 0.0956771 | J36: =POWER(I36, 2) -> 0.0091541075 | K36: =C36/C16*100 -> 88.893385 | L36: =K36-$K$47 -> 1.3258889 | M36: =ABS(L36) -> 1.3258889 | N36: =POWER(L36, 2) -> 1.7579813
A37: 2010 | B37: 3 | C37: 450.7 | D37: =C37-$C$47 -> -9.6833333 | E37: =ABS(D37) -> 9.6833333 | F37: =POWER(D37, 2) -> 93.766944 | G37: =(C37/C36)*100 -> 102.57169 | H37: =G37-$G$47 -> 1.7885689 | I37: =ABS(H37) -> 1.7885689 | J37: =POWER(I37, 2) -> 3.1989785 | K37: =C37/C17*100 -> 89.212193 | L37: =K37-$K$47 -> 1.6446975 | M37: =ABS(L37) -> 1.6446975 | N37: =POWER(L37, 2) -> 2.7050298
A38: 2011 | B38: 4 | C38: 453.9 | D38: =C38-$C$47 -> -6.4833333 | E38: =ABS(D38) -> 6.4833333 | F38: =POWER(D38, 2) -> 42.033611 | G38: =(C38/C37)*100 -> 100.71001 | H38: =G38-$G$47 -> -0.073113157 | I38: =ABS(H38) -> 0.073113157 | J38: =POWER(I38, 2) -> 0.0053455337 | K38: =C38/C18*100 -> 88.756355 | L38: =K38-$K$47 -> 1.1888594 | M38: =ABS(L38) -> 1.1888594 | N38: =POWER(L38, 2) -> 1.4133866
A39: 2012 | B39: 5 | C39: 460.4 | D39: =C39-$C$47 -> 0.016666667 | E39: =ABS(D39) -> 0.016666667 | F39: =POWER(D39, 2) -> 0.00027777778 | G39: =(C39/C38)*100 -> 101.43203 | H39: =G39-$G$47 -> 0.64891367 | I39: =ABS(H39) -> 0.64891367 | J39: =POWER(I39, 2) -> 0.42108896 | K39: =C39/C19*100 -> 88.863154 | L39: =K39-$K$47 -> 1.2956581 | M39: =ABS(L39) -> 1.2956581 | N39: =POWER(L39, 2) -> 1.67873
A40: 2013 | B40: 6 | C40: 464.4 | D40: =C40-$C$47 -> 4.0166667 | E40: =ABS(D40) -> 4.0166667 | F40: =POWER(D40, 2) -> 16.133611 | G40: =(C40/C39)*100 -> 100.86881 | H40: =G40-$G$47 -> 0.085689917 | I40: =ABS(H40) -> 0.085689917 | J40: =POWER(I40, 2) -> 0.0073427619 | K40: =C40/C20*100 -> 88.727551 | L40: =K40-$K$47 -> 1.1600549 | M40: =ABS(L40) -> 1.1600549 | N40: =POWER(L40, 2) -> 1.3457274
A41: 2014 | B41: 7 | C41: 464.5 | D41: =C41-$C$47 -> 4.1166667 | E41: =ABS(D41) -> 4.1166667 | F41: =POWER(D41, 2) -> 16.946944 | G41: =(C41/C40)*100 -> 100.02153 | H41: =G41-$G$47 -> -0.76158665 | I41: =ABS(H41) -> 0.76158665 | J41: =POWER(I41, 2) -> 0.58001423 | K41: =C41/C21*100 -> 88.17388 | L41: =K41-$K$47 -> 0.60638431 | M41: =ABS(L41) -> 0.60638431 | N41: =POWER(L41, 2) -> 0.36770194
A42: 2015 | B42: 8 | C42: 464.8 | D42: =C42-$C$47 -> 4.4166667 | E42: =ABS(D42) -> 4.4166667 | F42: =POWER(D42, 2) -> 19.506944 | G42: =(C42/C41)*100 -> 100.06459 | H42: =G42-$G$47 -> -0.71853424 | I42: =ABS(H42) -> 0.71853424 | J42: =POWER(I42, 2) -> 0.51629145 | K42: =C42/C22*100 -> 86.992326 | L42: =K42-$K$47 -> -0.57516931 | M42: =ABS(L42) -> 0.57516931 | N42: =POWER(L42, 2) -> 0.33081973
A43: 2016 | B43: 9 | C43: 472.3 | D43: =C43-$C$47 -> 11.916667 | E43: =ABS(D43) -> 11.916667 | F43: =POWER(D43, 2) -> 142.00694 | G43: =(C43/C42)*100 -> 101.6136 | H43: =G43-$G$47 -> 0.83047743 | I43: =ABS(H43) -> 0.83047743 | J43: =POWER(I43, 2) -> 0.68969277 | K43: =C43/C23*100 -> 86.249087 | L43: =K43-$K$47 -> -1.3184088 | M43: =ABS(L43) -> 1.3184088 | N43: =POWER(L43, 2) -> 1.7382017
A44: 2017 | B44: 10 | C44: 468.6 | D44: =C44-$C$47 -> 8.2166667 | E44: =ABS(D44) -> 8.2166667 | F44: =POWER(D44, 2) -> 67.513611 | G44: =(C44/C43)*100 -> 99.2166 | H44: =G44-$G$47 -> -1.5665202 | I44: =ABS(H44) -> 1.5665202 | J44: =POWER(I44, 2) -> 2.4539855 | K44: =C44/C24*100 -> 85.69861 | L44: =K44-$K$47 -> -1.8688856 | M44: =ABS(L44) -> 1.8688856 | N44: =POWER(L44, 2) -> 3.4927335
A45: 2018 | B45: 11 | C45: 473.7 | D45: =C45-$C$47 -> 13.316667 | E45: =ABS(D45) -> 13.316667 | F45: =POWER(D45, 2) -> 177.33361 | G45: =(C45/C44)*100 -> 101.08835 | H45: =G45-$G$47 -> 0.30522846 | I45: =ABS(H45) -> 0.30522846 | J45: =POWER(I45, 2) -> 0.093164412 | K45: =C45/C25*100 -> 85.197842 | L45: =K45-$K$47 -> -2.369654 | M45: =ABS(L45) -> 2.369654 | N45: =POWER(L45, 2) -> 5.61526
A46: 2019 | B46: 12 | C46: 475.5 | D46: =C46-$C$47 -> 15.116667 | E46: =ABS(D46) -> 15.116667 | F46: =POWER(D46, 2) -> 228.51361 | G46: =(C46/C45)*100 -> 100.37999 | H46: =G46-$G$47 -> -0.40313248 | I46: =ABS(H46) -> 0.40313248 | J46: =POWER(I46, 2) -> 0.1625158 | K46: =C46/C26*100 -> 84.729152 | L46: =K46-$K$47 -> -2.8383439 | M46: =ABS(L46) -> 2.8383439 | N46: =POWER(L46, 2) -> 8.0561961
...

Sheet 1.2
A1: Распределение добычи нефти по регионам, по годам, млн. т
A3: Показатель | C3: 2008 | D3: 2009 | E3: 2010 | F3: 2011 | G3: 2012 | H3: 2013 | I3: 2014 | J3: 2015 | K3: 2016 | L3: 2017 | M3: 2018 | N3: 2019 | O3: Среднее значение добычи по регионам за 2014-2019 | P3: Xmax | Q3: Xmin | R3: Амплитуда, R | S3: Q1 | T3: Q3 | U3: Медиана, Me | V3: Межквартильный размах, IQR | W3: Среднее линейное отклонение, L | X3: Дисперсия | Y3: Среднеквадратическое отклонение, СКО | Z3: Коэффициент осциляции (VR), % | AA3: Коэффициент линейного отклонения (VL), % | AB3: Коэффициент вариации (V), %
A4: А | B4: Б | C4: 1 | D4: 2 | E4: 3 | F4: 4 | G4: 5 | H4: 6 | I4: 7 | J4: 8 | K4: 9 | L4: 10 | M4: 11 | N4: 12 | O4: 13 | P4: 14 | Q4: 15 | R4: 16 | S4: 17 | T4: 18 | U4: 19 | V4: 20 | W4: 21 | X4: 23 | Y4: 24 | Z4: 25 | AA4: 26 | AB4: 27
A5: Всего | B5: 1 | C5: ='1.1'!C5 -> 488.6 | D5: ='1.1'!D5 -> 494.3 | E5: ='1.1'!E5 -> 505.2 | F5: ='1.1'!F5 -> 511.4 | G5: ='1.1'!G5 -> 518.1 | H5: ='1.1'!H5 -> 523.4 | I5: ='1.1'!I5 -> 526.8 | J5: ='1.1'!J5 -> 534.3 | ... N5: ='1.1'!N5 -> 561.2 | O5: =AVERAGE(C5:N5) -> 526.14167 | P5: =QUARTILE(C5:N5,4) -> 561.2 | Q5: =QUARTILE(C5:N5, 0) -> 488.6 | R5: =P5-Q5 -> 72.6 | S5: =QUARTILE(C5:N5,1) -> 509.85 | T5: =QUARTILE(C5:N5, 3) -> 547 | U5: =QUARTILE(C5:N5, 2) -> 525.1 | V5: 525,1 (Q1-Q3: 509,9-547,0) | W5: =SUM(E16:E27)/COUNTA(E16:E27) -> 19.308333 | X5: =SUM(F16:F27)/COUNTA(F16:F27) -> 518.84576 | Y5: =SQRT(X5) -> 22.778186 | Z5: =R5/O5*100 -> 13.798565 | AA5: =W5/O5*100 -> 3.6697974 | AB5: =Y5/O5*100 -> 4.3292876
A6: Европейская часть | B6: 2 | C6: УЧЕТ НЕ ОСУЩЕСТВЛЯЛСЯ (н/д) | I6: 155 | J6: 159 | K6: 163.3 | L6: 163.3 | M6: 164.4 | N6: 165.7 | O6: =AVERAGE(I6:N6) -> 161.78333 | P6: =QUARTILE(C6:N6,4) -> 165.7 | Q6: =QUARTILE(C6:N6, 0) -> 155 | R6: =P6-Q6 -> 10.7 | S6: =QUARTILE(C6:N6,1) -> 160.075 | T6: =QUARTILE(C6:N6, 3) -> 164.125 | U6: =QUARTILE(C6:N6, 2) -> 163.3 | V6: 163,3 (Q1-Q3: 160,1-164,1) | W6: =SUM(E43:E48)/COUNTA(E43:E48) -> 3.1888889 | X6: =SUM(F43:F48)/COUNTA(F43:F48) -> 13.424722 | Y6: =SQRT(X6) -> 3.6639763 | Z6: =R6/O6*100 -> 6.6137839 | AA6: =W6/O6*100 -> 1.9710862 | AB6: =Y6/O6*100 -> 2.2647427
A7: Западная Сибирь | B7: 3 | I7: 313 | J7: 311.8 | K7: 315.5 | L7: 313.6 | M7: 316.9 | N7: 319.5 | O7: =AVERAGE(I7:N7) -> 315.05 | P7: =QUARTILE(C7:N7,4) -> 319.5 | Q7: =QUARTILE(C7:N7, 0) -> 311.8 | R7: =P7-Q7 -> 7.7 | S7: =QUARTILE(C7:N7,1) -> 313.15 | T7: =QUARTILE(C7:N7, 3) -> 316.55 | U7: =QUARTILE(C7:N7, 2) -> 314.55 | V7: 314,6 (Q1-Q3: 313,2-316,6) | W7: =SUM(E64:E69)/COUNTA(E64:E69) -> 2.25 | X7: =SUM(F64:F69)/COUNTA(F64:F69) -> 6.7158333 | Y7: =SQRT(X7) -> 2.5914925 | Z7: =R7/O7*100 -> 2.4440565 | AA7: =W7/O7*100 -> 0.71417235 | AB7: =Y7/O7*100 -> 0.82256546
A8: Восточная Сибирь и Дальний Восток | B8: 4 | I8: 58.8 | J8: 63.6 | K8: 68.7 | L8: 69.9 | M8: 74.6 | N8: 76 | O8: =AVERAGE(I8:N8) -> 68.6 | P8: =QUARTILE(C8:N8,4) -> 76 | Q8: =QUARTILE(C8:N8, 0) -> 58.8 | R8: =P8-Q8 -> 17.2 | S8: =QUARTILE(C8:N8,1) -> 64.875 | T8: =QUARTILE(C8:N8, 3) -> 73.425 | U8: =QUARTILE(C8:N8, 2) -> 69.3 | V8: 69,3 (Q1-Q3: 64,9-73,4) | W8: =SUM(E85:E90)/COUNTA(E85:E90) -> 4.9333333 | X8: =SUM(F85:F90)/COUNTA(F85:F90) -> 35.583333 | Y8: =SQRT(X8) -> 5.9651767 | Z8: =R8/O8*100 -> 25.072886 | AA8: =W8/O8*100 -> 7.191448 | AB8: =Y8/O8*100 -> 8.6955929
A10: Источник: данные ЦДУ ТЭК.
A12: Расчетные значения добычи нефти (всего), млн.т
A14: Показатель | C14: Добыча нефти | D14: Х-Хср | E14: |Х-Хср| | F14: (Х-Хср)2 | G14: Сравнение с предущим периодом, % | H14: Х1-Хср | I14: |Х1-Хср| | J14: (Х1-Хср)2
A15: А | B15: Б | C15: В | D15: 1 | E15: 2 | F15: 3 | G15: 4 | H15: 5 | I15: 6 | J15: 7
A16: 2008 | B16: 1 | C16: {=TRANSPOSE(C5:N5)} -> 488.6 | D16: =C16-$C$28 -> -37.541667 | E16: =ABS(D16) -> 37.541667 | F16: =POWER(E16,2) -> 1409.3767 | G16: - | H16: - | I16: - | J16: -
A17: 2009 | B17: 2 | C17: 494.3 | D17: =C17-$C$28 -> -31.841667 | E17: =ABS(D17) -> 31.841667 | F17: =POWER(E17,2) -> 1013.8917 | G17: =C17/C16*100 -> 101.1666 | H17: =G17-$G$28 -> -0.10075793 | I17: =ABS(H17:H27) -> 0.10075793 | J17: =POWER(I17, 2) -> 0.010152161
A18: 2010 | B18: 3 | C18: 505.2 | D18: =C18-$C$28 -> -20.941667 | E18: =ABS(D18) -> 20.941667 | F18: =POWER(E18,2) -> 438.5534 | G18: =C18/C17*100 -> 102.20514 | H18: =G18-$G$28 -> 0.9377822 | I18: =ABS(H18:H28) -> 0.9377822 | J18: =POWER(I18, 2) -> 0.87943546
A19: 2011 | B19: 4 | C19: 511.4 | D19: =C19-$C$28 -> -14.741667 | E19: =ABS(D19) -> 14.741667 | F19: =POWER(E19,2) -> 217.31674 | G19: =C19/C18*100 -> 101.22724 | H19: =G19-$G$28 -> -0.040119639 | I19: =ABS(H19:H29) -> 0.040119639 | J19: =POWER(I19, 2) -> 0.0016095854
A20: 2012 | B20: 5 | C20: 518.1 | D20: =C20-$C$28 -> -8.0416667 | E20: =ABS(D20) -> 8.0416667 | F20: =POWER(E20,2) -> 64.668403 | G20: =C20/C19*100 -> 101.31013 | H20: =G20-$G$28 -> 0.042772681 | I20: =ABS(H20:H30) -> 0.042772681 | J20: =POWER(I20, 2) -> 0.0018295022
A21: 2013 | B21: 6 | C21: 523.4 | D21: =C21-$C$28 -> -2.7416667 | E21: =ABS(D21) -> 2.7416667 | F21: =POWER(E21,2) -> 7.5167361 | G21: =C21/C20*100 -> 101.02297 | H21: =G21-$G$28 -> -0.24438784 | I21: =ABS(H21:H31) -> 0.24438784 | J21: =POWER(I21, 2) -> 0.059725415
A22: 2014 | B22: 7 | C22: 526.8 | D22: =C22-$C$28 -> 0.65833333 | E22: =ABS(D22) -> 0.65833333 | F22: =POWER(E22,2) -> 0.43340278 | G22: =C22/C21*100 -> 100.6496 | H22: =G22-$G$28 -> -0.6177576 | I22: =ABS(H22:H32) -> 0.6177576 | J22: =POWER(I22, 2) -> 0.38162445
A23: 2015 | B23: 8 | C23: 534.3 | D23: =C23-$C$28 -> 8.1583333 | E23: =ABS(D23) -> 8.1583333 | F23: =POWER(E23,2) -> 66.558403 | G23: =C23/C22*100 -> 101.42369 | H23: =G23-$G$28 -> 0.15633383 | I23: =ABS(H23:H33) -> 0.15633383 | J23: =POWER(I23, 2) -> 0.024440266
A24: 2016 | B24: 9 | C24: 547.6 | D24: =C24-$C$28 -> 21.458333 | E24: =ABS(D24) -> 21.458333 | F24: =POWER(E24,2) -> 460.46007 | G24: =C24/C23*100 -> 102.48924 | H24: =G24-$G$28 -> 1.2218819 | I24: =ABS(H24:H34) -> 1.2218819 | J24: =POWER(I24, 2) -> 1.4929953
A25: 2017 | B25: 10 | C25: 546.8 | D25: =C25-$C$28 -> 20.658333 | E25: =ABS(D25) -> 20.658333 | F25: =POWER(E25,2) -> 426.76674 | G25: =C25/C24*100 -> 99.853908 | H25: =G25-$G$28 -> -1.4134484 | I25: =ABS(H25:H35) -> 1.4134484 | J25: =POWER(I25, 2) -> 1.9978364
A26: 2018 | B26: 11 | C26: 556 | D26: =C26-$C$28 -> 29.858333 | E26: =ABS(D26) -> 29.858333 | F26: =POWER(E26,2) -> 891.52007 | G26: =C26/C25*100 -> 101.68252 | H26: =G26-$G$28 -> 0.41516008 | I26: =ABS(H26:H36) -> 0.41516008 | J26: =POWER(I26, 2) -> 0.17235789
A27: 2019 | B27: 12 | C27: 561.2 | D27: =C27-$C$28 -> 35.058333 | E27: =ABS(D27) -> 35.058333 | F27: =POWER(E27,2) -> 1229.0867 | G27: =C27/C26*100 -> 100.93525 | H27: =G27-$G$28 -> -0.33210458 | I27: =ABS(H27:H37) -> 0.33210458 | J27: =POWER(I27, 2) -> 0.11029345
A28: Среднее значение | B28: 13 | C28: =AVERAGE(C16:C27) -> 526.14167 | D28: - | E28: - | F28: - | G28: =POWER(PRODUCT(G17:G27),1/COUNTA(G17:G27)) -> 101.26736 | H28: - | I28: - | J28: -
A30: Источник: расчеты автора на основе данных ЦДУ ТЭК
A33: Расчетные значения добычи нефти по Европейской части, млн.т
A35: Показатель | C35: Добыча нефти | D35: Х-Хср | E35: |Х-Хср| | F35: (Х-Хср)2 | G35: Сравнение с предущим периодом, % | H35: Х1-Хср | I35: |Х1-Хср| | J35: (Х1-Хср)2 | K35: Добыча нефти относительно общего количества | L35: Х1-Хср | M35: |Х1-Хср| | N35: (Х1-Хср)2
A36: А | B36: Б | C36: В | D36: 1 | E36: 2 | F36: 3 | G36: 4 | H36: 5 | I36: 6 | J36: 7 | K36: 4 | L36: 5 | M36: 6 | N36: 7
A37: 2008 | B37: 1 | C37: - | D37: - | E37: - | F37: - | G37: - | H37: - | I37: - | J37: - | K37: - | L37: - | M37: - | N37: -
A38: 2009 | B38: 2 | C38: - | D38: - | E38: - | F38: - | G38: - | H38: - | I38: - | J38: - | K38: - | L38: - | M38: - | N38: -
A39: 2010 | B39: 3 | C39: - | D39: - | E39: - | F39: - | G39: - | H39: - | I39: - | J39: - | K39: - | L39: - | M39: - | N39: -
A40: 2011 | B40: 4 | C40: - | D40: - | E40: - | F40: - | G40: - | H40: - | I40: - | J40: - | K40: - | L40: - | M40: - | N40: -
A41: 2012 | B41: 5 | C41: - | D41: - | E41: - | F41: - | G41: - | H41: - | I41: - | J41: - | K41: - | L41: - | M41: - | N41: -
A42: 2013 | B42: 6 | C42: - | D42: - | E42: - | F42: - | G42: - | H42: - | I42: - | J42: - | K42: - | L42: - | M42: - | N42: -
A43: 2014 | B43: 7 | C43: {=TRANSPOSE(I6:N6)} -> 155 | D43: =C43-$C$49 -> -6.7833333 | E43: =ABS(D43) -> 6.7833333 | F43: =POWER(E43,2) -> 46.013611 | G43: - | H43: - | I43: - | J43: - | K43: =C43/C22*100 -> 29.422931 | L43: =K43-$K$49 -> -0.23732892 | M43: =ABS(L43) -> 0.23732892 | N43: =POWER(M43, 2) -> 0.056325015
A44: 2015 | B44: 8 | C44: 159 | D44: =C44-$C$49 -> -2.7833333 | E44: =ABS(D44) -> 2.7833333 | F44: =POWER(E44,2) -> 7.7469444 | G44: =C44/C43*100 -> 102.58065 | H44: =G44-$G$49 -> 1.2366171 | I44: =ABS(H44) -> 1.2366171 | J44: =POWER(I44, 2) -> 1.5292218 | K44: =C44/C23*100 -> 29.758563 | L44: =K44-$K$49 -> 0.098302785 | M44: =ABS(L44) -> 0.098302785 | N44: =POWER(M44, 2) -> 0.0096634376
A45: 2016 | B45: 9 | C45: 163.3 | D45: =C45-$C$49 -> 1.5166667 | E45: =ABS(D45) -> 1.5166667 | F45: =POWER(E45,2) -> 2.3002778 | G45: =C45/C44*100 -> 102.7044 | H45: =G45-$G$49 -> 1.3603744 | I45: =ABS(H45) -> 1.3603744 | J45: =POWER(I45, 2) -> 1.8506186 | K45: =C45/C24*100 -> 29.821037 | L45: =K45-$K$49 -> 0.16077743 | M45: =ABS(L45) -> 0.16077743 | N45: =POWER(M45, 2) -> 0.025849383
A46: 2017 | B46: 10 | C46: 163.3 | D46: =C46-$C$49 -> 1.5166667 | E46: =ABS(D46) -> 1.5166667 | F46: =POWER(E46,2) -> 2.3002778 | G46: =C46/C45*100 -> 100 | H46: =G46-$G$49 -> -1.3440281 | I46: =ABS(H46) -> 1.3440281 | J46: =POWER(I46, 2) -> 1.8064115 | K46: =C46/C25*100 -> 29.864667 | L46: =K46-$K$49 -> 0.20440733 | M46: =ABS(L46) -> 0.20440733 | N46: =POWER(M46, 2) -> 0.041782358
A47: 2018 | B47: 11 | C47: 164.4 | D47: =C47-$C$49 -> 2.6166667 | E47: =ABS(D47) -> 2.6166667 | F47: =POWER(E47,2) -> 6.8469444 | G47: =C47/C46*100 -> 100.67361 | H47: =G47-$G$49 -> -0.67042123 | I47: =ABS(H47) -> 0.67042123 | J47: =POWER(I47, 2) -> 0.44946462 | K47: =C47/C26*100 -> 29.568345 | L47: =K47-$K$49 -> -0.091914496 | M47: =ABS(L47) -> 0.091914496 | N47: =POWER(M47, 2) -> 0.0084482747
A48: 2019 | B48: 12 | C48: 165.7 | D48: =C48-$C$49 -> 3.9166667 | E48: =ABS(D48) -> 3.9166667 | F48: =POWER(E48,2) -> 15.340278 | G48: =C48/C47*100 -> 100.79075 | H48: =G48-$G$49 -> -0.55327383 | I48: =ABS(H48) -> 0.55327383 | J48: =POWER(I48, 2) -> 0.30611193 | K48: =C48/C27*100 -> 29.526016 | L48: =K48-$K$49 -> -0.13424414 | M48: =ABS(L48) -> 0.13424414 | N48: =POWER(M48, 2) -> 0.018021489
...

Sheet 1.3
A1: Добыча нефти по новым источникам добычи, по годам, млн. т
A3: Показатель | C3: 2008 | D3: 2009 | E3: 2010 | F3: 2011 | G3: 2012 | H3: 2013 | I3: 2014 | J3: 2015 | K3: 2016 | L3: 2017 | M3: 2018 | N3: 2019 | O3: Среднее значение добычи за 2008-2019 | P3: Xmax | Q3: Xmin | R3: Амплитуда, R | S3: Q1 | T3: Q3 | U3: Медиана, Ме | V3: Межквартильный размах, IQR | W3: Среднее линейное отклонение, L | X3: Дисперсия | Y3: Среднеквадратическое отклонение, СКО | Z3: Коэффициент осциляции (VR), % | AA3: Коэффициент линейного отклонения (VL), % | AB3: Коэффициент вариации (V), %
A4: А | B4: Б | C4: 1 | D4: 2 | E4: 3 | F4: 4 | G4: 5 | H4: 6 | I4: 7 | J4: 8 | K4: 9 | L4: 10 | M4: 11 | N4: 12 | O4: 13 | P4: 14 | Q4: 15 | R4: 16 | S4: 17 | T4: 18 | U4: 19 | V4: 20 | W4: 21 | X4: 23 | Y4: 24 | Z4: 25 | AA4: 26 | AB4: 27
A5: Всего | B5: 1 | C5: ='1.1'!C5 -> 488.6 | D5: ='1.1'!D5 -> 494.3 | E5: ='1.1'!E5 -> 505.2 | F5: ='1.1'!F5 -> 511.4 | G5: ='1.1'!G5 -> 518.1 | H5: ='1.1'!H5 -> 523.4 | I5: ='1.1'!I5 -> 526.8 | J5: ='1.1'!J5 -> 534.3 | ... N5: ='1.1'!N5 -> 561.2 | O5: =AVERAGE(C5:N5) -> 526.14167 | P5: =QUARTILE(C5:N5,4) -> 561.2 | Q5: =QUARTILE(C5:N5, 0) -> 488.6 | R5: =P5-Q5 -> 72.6 | S5: =QUARTILE(C5:N5,1) -> 509.85 | T5: =QUARTILE(C5:N5, 3) -> 547 | U5: =QUARTILE(C5:N5, 2) -> 525.1 | V5: 525,1 (Q1-Q3: 509,9-547,0) | W5: =SUM(E16:E27)/COUNTA(E16:E27) -> 19.308333 | X5: =SUM(F16:F27)/COUNTA(F16:F27) -> 518.84576 | Y5: =SQRT(X5) -> 22.778186 | Z5: =R5/O5*100 -> 13.798565 | AA5: =W5/O5*100 -> 3.6697974 | AB5: =Y5/O5*100 -> 4.3292876
A6: Добыча нефти на новых месторождениях ("гринфилдах") | B6: 2 | C6: н/д | D6: 31.4 | E6: 38 | F6: 37.4 | G6: 37.6 | H6: 37.3 | I6: 40.8 | J6: 20.2 | K6: 31 | L6: 37 | M6: 42 | N6: 41.3 | O6: =AVERAGE(C6:N6) -> 35.818182 | P6: =QUARTILE(D6:N6,4) -> 42 | Q6: =QUARTILE(D6:N6, 0) -> 20.2 | R6: =P6-Q6 -> 21.8 | S6: =QUARTILE(D6:N6,1) -> 34.2 | T6: =QUARTILE(D6:N6, 3) -> 39.4 | U6: =QUARTILE(D6:N6, 2) -> 37.4 | V6: 37,4 (Q1-Q3: 34,2-39,4) | W6: =SUM(E39:E49)/COUNTA(E39:E49) -> 4.5190083 | X6: =SUM(F39:F49)/COUNTA(F39:F49) -> 35.797851 | Y6: =SQRT(X6) -> 5.9831306 | Z6: =R6/O6*100 -> 60.862944 | AA6: =W6/O6*100 -> 12.616521 | AB6: =Y6/O6*100 -> 16.704172
A7: Добыча нефти на шельфе | B7: 3 | C7: н/д | D7: 15.3 | E7: 14.7 | F7: 15.4 | G7: 14.6 | H7: 15 | I7: 16.2 | J7: 19.1 | K7: 22.3 | L7: 25.7 | M7: 29.1 | N7: 30 | O7: =AVERAGE(C7:N7) -> 19.763636 | P7: =QUARTILE(D7:N7,4) -> 30 | Q7: =QUARTILE(D7:N7, 0) -> 14.6 | R7: =P7-Q7 -> 15.4 | S7: =QUARTILE(D7:N7,1) -> 15.15 | T7: =QUARTILE(D7:N7, 3) -> 24 | U7: =QUARTILE(D7:N7, 2) -> 16.2 | V7: 16,2 (Q1-Q3: 15,2-24,0) | W7: =SUM(E60:E70)/COUNTA(E60:E70) -> 16.054545 | X7: =SUM(F60:F70)/COUNTA(F60:F70) -> 290.54165 | Y7: =SQRT(X7) -> 17.045282 | Z7: =R7/O7*100 -> 77.920883 | AA7: =W7/O7*100 -> 81.232751 | AB7: =Y7/O7*100 -> 86.245679
A9: Источник: данные ЦДУ ТЭК.
A12: Расчетные значения добычи нефти по новым источникам, по годам (всего), млн.т
A14: Год | C14: Добыча нефти | D14: Х-Хср | E14: |Х-Хср| | F14: (Х-Хср)2
A15: А | B15: Б | C15: В | D15: 1 | E15: 2 | F15: 3
A16: 2008 | B16: 1 | C16: {=TRANSPOSE(C5:N5)} -> 488.6 | D16: =C16-$C$28 -> -37.541667 | E16: =ABS(D16) -> 37.541667 | F16: =POWER(E16,2) -> 1409.3767
A17: 2009 | B17: 2 | C17: 494.3 | D17: =C17-$C$28 -> -31.841667 | E17: =ABS(D17) -> 31.841667 | F17: =POWER(E17,2) -> 1013.8917
A18: 2010 | B18: 3 | C18: 505.2 | D18: =C18-$C$28 -> -20.941667 | E18: =ABS(D18) -> 20.941667 | F18: =POWER(E18,2) -> 438.5534
A19: 2011 | B19: 4 | C19: 511.4 | D19: =C19-$C$28 -> -14.741667 | E19: =ABS(D19) -> 14.741667 | F19: =POWER(E19,2) -> 217.31674
A20: 2012 | B20: 5 | C20: 518.1 | D20: =C20-$C$28 -> -8.0416667 | E20: =ABS(D20) -> 8.0416667 | F20: =POWER(E20,2) -> 64.668403
A21: 2013 | B21: 6 | C21: 523.4 | D21: =C21-$C$28 -> -2.7416667 | E21: =ABS(D21) -> 2.7416667 | F21: =POWER(E21,2) -> 7.5167361
A22: 2014 | B22: 7 | C22: 526.8 | D22: =C22-$C$28 -> 0.65833333 | E22: =ABS(D22) -> 0.65833333 | F22: =POWER(E22,2) -> 0.43340278
A23: 2015 | B23: 8 | C23: 534.3 | D23: =C23-$C$28 -> 8.1583333 | E23: =ABS(D23) -> 8.1583333 | F23: =POWER(E23,2) -> 66.558403
A24: 2016 | B24: 9 | C24: 547.6 | D24: =C24-$C$28 -> 21.458333 | E24: =ABS(D24) -> 21.458333 | F24: =POWER(E24,2) -> 460.46007
A25: 2017 | B25: 10 | C25: 546.8 | D25: =C25-$C$28 -> 20.658333 | E25: =ABS(D25) -> 20.658333 | F25: =POWER(E25,2) -> 426.76674
A26: 2018 | B26: 11 | C26: 556 | D26: =C26-$C$28 -> 29.858333 | E26: =ABS(D26) -> 29.858333 | F26: =POWER(E26,2) -> 891.52007
A27: 2019 | B27: 12 | C27: 561.2 | D27: =C27-$C$28 -> 35.058333 | E27: =ABS(D27) -> 35.058333 | F27: =POWER(E27,2) -> 1229.0867
A28: Среднее значение | B28: 13 | C28: =AVERAGE(C16:C27) -> 526.14167 | D28: - | E28: - | F28: -
A30: Источник: расчеты автора на основе данных ЦДУ ТЭК
A34: Расчетные значения добычи нефти на новых источниках "гринфилдах", по годам (всего), млн.т
A36: Год | C36: Добыча нефти | D36: Х-Хср | E36: |Х-Хср| | F36: (Х-Хср)2 | G36: Добыча нефти в общем количестве, % | H36: Х1-Хср | I36: |Х1-Хср| | J36: (Х1-Хср)2
A37: А | B37: Б | C37: В | D37: 1 | E37: 2 | F37: 3 | G37: 4 | H37: 5 | I37: 6 | J37: 7
A38: 2008 | B38: 1 | C38: - | D38: - | E38: - | F38: - | G38: - | H38: - | I38: - | J38: -
A39: 2009 | B39: 2 | C39: {=TRANSPOSE(D6:N6)} -> 31.4 | D39: =C39-$C$50 -> -4.4181818 | E39: =ABS(D39) -> 4.4181818 | F39: =POWER(E39,2) -> 19.520331 | G39: =C39/C17*100 -> 6.3524176 | H39: =G39-$G$50 -> -0.41464007 | I39: =ABS(H39) -> 0.41464007 | J39: =POWER(I39,2) -> 0.17192638
A40: 2010 | B40: 3 | C40: 38 | D40: =C40-$C$50 -> 2.1818182 | E40: =ABS(D40) -> 2.1818182 | F40: =POWER(E40,2) -> 4.7603306 | G40: =C40/C18*100 -> 7.5217736 | H40: =G40-$G$50 -> 0.75471593 | I40: =ABS(H40) -> 0.75471593 | J40: =POWER(I40,2) -> 0.56959613
A41: 2011 | B41: 4 | C41: 37.4 | D41: =C41-$C$50 -> 1.5818182 | E41: =ABS(D41) -> 1.5818182 | F41: =POWER(E41,2) -> 2.5021488 | G41: =C41/C19*100 -> 7.3132577 | H41: =G41-$G$50 -> 0.5462001 | I41: =ABS(H41) -> 0.5462001 | J41: =POWER(I41,2) -> 0.29833455
A42: 2012 | B42: 5 | C42: 37.6 | D42: =C42-$C$50 -> 1.7818182 | E42: =ABS(D42) -> 1.7818182 | F42: =POWER(E42,2) -> 3.174876 | G42: =C42/C20*100 -> 7.2572862 | H42: =G42-$G$50 -> 0.49022861 | I42: =ABS(H42) -> 0.49022861 | J42: =POWER(I42,2) -> 0.24032409
A43: 2013 | B43: 6 | C43: 37.3 | D43: =C43-$C$50 -> 1.4818182 | E43: =ABS(D43) -> 1.4818182 | F43: =POWER(E43,2) -> 2.1957851 | G43: =C43/C21*100 -> 7.1264807 | H43: =G43-$G$50 -> 0.35942308 | I43: =ABS(H43) -> 0.35942308 | J43: =POWER(I43,2) -> 0.12918495
A44: 2014 | B44: 7 | C44: 40.8 | D44: =C44-$C$50 -> 4.9818182 | E44: =ABS(D44) -> 4.9818182 | F44: =POWER(E44,2) -> 24.818512 | G44: =C44/C22*100 -> 7.7448747 | H44: =G44-$G$50 -> 0.97781709 | I44: =ABS(H44) -> 0.97781709 | J44: =POWER(I44,2) -> 0.95612626
A45: 2015 | B45: 8 | C45: 20.2 | D45: =C45-$C$50 -> -15.618182 | E45: =ABS(D45) -> 15.618182 | F45: =POWER(E45,2) -> 243.9276 | G45: =C45/C23*100 -> 3.7806476 | H45: =G45-$G$50 -> -2.98641 | I45: =ABS(H45) -> 2.98641 | J45: =POWER(I45,2) -> 8.918645
A46: 2016 | B46: 9 | C46: 31 | D46: =C46-$C$50 -> -4.8181818 | E46: =ABS(D46) -> 4.8181818 | F46: =POWER(E46,2) -> 23.214876 | G46: =C46/C24*100 -> 5.6610665 | H46: =G46-$G$50 -> -1.1059912 | I46: =ABS(H46) -> 1.1059912 | J46: =POWER(I46,2) -> 1.2232164
A47: 2017 | B47: 10 | C47: 37 | D47: =C47-$C$50 -> 1.1818182 | E47: =ABS(D47) -> 1.1818182 | F47: =POWER(E47,2) -> 1.3966942 | G47: =C47/C25*100 -> 6.7666423 | H47: =G47-$G$50 -> -0.00041534323 | I47: =ABS(H47) -> 0.00041534323 | J47: =POWER(I47,2) -> 1.7251e-07
A48: 2018 | B48: 11 | C48: 42 | D48: =C48-$C$50 -> 6.1818182 | E48: =ABS(D48) -> 6.1818182 | F48: =POWER(E48,2) -> 38.214876 | G48: =C48/C26*100 -> 7.5539568 | H48: =G48-$G$50 -> 0.78689921 | I48: =ABS(H48) -> 0.78689921 | J48: =POWER(I48,2) -> 0.61921037
A49: 2019 | B49: 12 | C49: 41.3 | D49: =C49-$C$50 -> 5.4818182 | E49: =ABS(D49) -> 5.4818182 | F49: =POWER(E49,2) -> 30.050331 | G49: =C49/C27*100 -> 7.3592302 | H49: =G49-$G$50 -> 0.5921726 | I49: =ABS(H49) -> 0.5921726 | J49: =POWER(I49,2) -> 0.35066838
A50: Среднее значение | B50: 13 | C50: =AVERAGE(C39:C49) -> 35.818182 | D50: - | E50: - | F50: - | G50: =AVERAGE(G39:G49) -> 6.7670576 | H50: - | I50: - | J50: -
...

Sheet 1.4
A1: Основные сведения о фонде скважин, осуществляющих добычу нефти
A3: Показатель | C3: 2008 | D3: 2009 | E3: 2010 | F3: 2011 | G3: 2012 | H3: 2013 | I3: 2014 | J3: 2015 | K3: 2016 | L3: 2017 | M3: 2018 | N3: 2019 | O3: Среднее значение по фонду скважин | P3: Xmax | Q3: Xmin | R3: Амплитуда, R | S3: Q1 | T3: Q3 | U3: Медиана, МЕ | V3: Межквартильный размах, IQR | W3: Среднее линейное отклонение, L | X3: Дисперсия | Y3: Среднеквадратическое отклонение, СКО | Z3: Коэффициент осциляции (VR), % | AA3: Коэффициент линейного отклонения (VL), % | AB3: Коэффициент вариации (V), %
A4: А | B4: Б | C4: 1 | D4: 2 | E4: 3 | F4: 4 | G4: 5 | H4: 6 | I4: 7 | J4: 8 | K4: 9 | L4: 10 | M4: 11 | N4: 12 | O4: 13 | P4: 14 | Q4: 15 | R4: 16 | S4: 17 | T4: 18 | U4: 19 | V4: 20 | W4: 21 | X4: 23 | Y4: 24 | Z4: 25 | AA4: 26 | AB4: 27
A5: Фонд скважин, тыс. скважин | B5: 1 | C5: 157.8 | D5: 158.8 | E5: 159.4 | F5: 160.4 | G5: 162.7 | H5: 166 | I5: 168.3 | J5: 170.2 | K5: 173.1 | L5: 175.3 | M5: 177.5 | N5: 180.4 | O5: =AVERAGE(C5:N5) -> 167.49167 | P5: =QUARTILE(C5:N5,4) -> 180.4 | Q5: =QUARTILE(C5:N5, 0) -> 157.8 | R5: =P5-Q5 -> 22.6 | S5: =QUARTILE(C5:N5,1) -> 160.15 | T5: =QUARTILE(C5:N5, 3) -> 173.65 | U5: =QUARTILE(C5:N5, 2) -> 167.15 | V5: 167,2 (Q1-Q3: 160,2-173,7) | W5: =SUM(E15:E26)/COUNTA(E15:E26) -> 6.6416667 | X5: =SUM(F15:F26)/COUNTA(F15:F26) -> 56.469097 | Y5: =SQRT(X5) -> 7.5145923 | Z5: =R5/O5*100 -> 13.493209 | AA5: =W5/O5*100 -> 3.9653714 | AB5: =Y5/O5*100 -> 4.486547
A6: Доля скважин, дающих продукцию, % | B6: 2 | C6: 0.841 | D6: 0.837 | E6: 0.847 | F6: 0.853 | G6: 0.855 | H6: 0.868 | I6: 0.869 | J6: 0.874 | K6: 0.875 | L6: 0.86 | M6: 0.874 | N6: 0.859 | O6: =AVERAGE(C6:N6) -> 0.85933333 | P6: =QUARTILE(D6:N6,4) -> 0.875 | Q6: =QUARTILE(D6:N6, 0) -> 0.837 | R6: =P6-Q6 -> 0.038 | S6: =QUARTILE(D6:N6,1) -> 0.854 | T6: =QUARTILE(D6:N6, 3) -> 0.8715 | U6: =QUARTILE(D6:N6, 2) -> 0.86 | V6: 0,9 (Q1-Q3: 0,0-0,9) | W6: =SUM(E36:E47)/COUNTA(E36:E47) -> 0.010666667 | X6: =SUM(F36:F47)/COUNTA(F36:F47) -> 0.00015755556 | Y6: =SQRT(X6) -> 0.012552114 | Z6: =R6/O6*100 -> 4.4220326 | AA6: =W6/O6*100 -> 1.2412723 | AB6: =Y6/O6*100 -> 1.4606804
A8: Источник: данные ЦДУ ТЭК.
A11: Расчетные значения по фонду скважин, тыс.скважин
A13: Год | C13: Фонд скважин | D13: Х-Хср | E13: |Х-Хср| | F13: (Х-Хср)2 | G13: Сравнение с предущим периодом, % | H13: Х1-Хср | I13: |Х1-Хср| | J13: (Х1-Хср)2
A14: А | B14: Б | C14: В | D14: 1 | E14: 2 | F14: 3 | G14: 4 | H14: 5 | I14: 6 | J14: 7
A15: 2008 | B15: 1 | C15: {=TRANSPOSE(C5:N5)} -> 157.8 | D15: =C15-$C$27 -> -9.6916667 | E15: =ABS(D15) -> 9.6916667 | F15: =POWER(E15, 2) -> 93.928403 | G15: - | H15: - | I15: - | J15: -
A16: 2009 | B16: 2 | C16: 158.8 | D16: =C16-$C$27 -> -8.6916667 | E16: =ABS(D16) -> 8.6916667 | F16: =POWER(E16, 2) -> 75.545069 | G16: =C16/C15*100 -> 100.63371 | H16: =G16-$G$27 -> -0.5905214 | I16: =ABS(H16:H26) -> 0.5905214 | J16: =POWER(I16, 2) -> 0.34871553
A17: 2010 | B17: 3 | C17: 159.4 | D17: =C17-$C$27 -> -8.0916667 | E17: =ABS(D17) -> 8.0916667 | F17: =POWER(E17, 2) -> 65.475069 | G17: =C17/C16*100 -> 100.37783 | H17: =G17-$G$27 -> -0.84640121 | I17: =ABS(H17:H27) -> 0.84640121 | J17: =POWER(I17, 2) -> 0.71639501
A18: 2011 | B18: 4 | C18: 160.4 | D18: =C18-$C$27 -> -7.0916667 | E18: =ABS(D18) -> 7.0916667 | F18: =POWER(E18, 2) -> 50.291736 | G18: =C18/C17*100 -> 100.62735 | H18: =G18-$G$27 -> -0.59688239 | I18: =ABS(H18:H28) -> 0.59688239 | J18: =POWER(I18, 2) -> 0.35626859
A19: 2012 | B19: 5 | C19: 162.7 | D19: =C19-$C$27 -> -4.7916667 | E19: =ABS(D19) -> 4.7916667 | F19: =POWER(E19, 2) -> 22.960069 | G19: =C19/C18*100 -> 101.43392 | H19: =G19-$G$27 -> 0.20968025 | I19: =ABS(H19:H29) -> 0.20968025 | J19: =POWER(I19, 2) -> 0.043965807
A20: 2013 | B20: 6 | C20: 166 | D20: =C20-$C$27 -> -1.4916667 | E20: =ABS(D20) -> 1.4916667 | F20: =POWER(E20, 2) -> 2.2250694 | G20: =C20/C19*100 -> 102.02827 | H20: =G20-$G$27 -> 0.80403793 | I20: =ABS(H20:H30) -> 0.80403793 | J20: =POWER(I20, 2) -> 0.646477
A21: 2014 | B21: 7 | C21: 168.3 | D21: =C21-$C$27 -> 0.80833333 | E21: =ABS(D21) -> 0.80833333 | F21: =POWER(E21, 2) -> 0.65340278 | G21: =C21/C20*100 -> 101.38554 | H21: =G21-$G$27 -> 0.16130721 | I21: =ABS(H21:H31) -> 0.16130721 | J21: =POWER(I21, 2) -> 0.026020015
A22: 2015 | B22: 8 | C22: 170.2 | D22: =C22-$C$27 -> 2.7083333 | E22: =ABS(D22) -> 2.7083333 | F22: =POWER(E22, 2) -> 7.3350694 | G22: =C22/C21*100 -> 101.12894 | H22: =G22-$G$27 -> -0.09529854 | I22: =ABS(H22:H32) -> 0.09529854 | J22: =POWER(I22, 2) -> 0.0090818116
A23: 2016 | B23: 9 | C23: 173.1 | D23: =C23-$C$27 -> 5.6083333 | E23: =ABS(D23) -> 5.6083333 | F23: =POWER(E23, 2) -> 31.453403 | G23: =C23/C22*100 -> 101.70388 | H23: =G23-$G$27 -> 0.47964283 | I23: =ABS(H23:H33) -> 0.47964283 | J23: =POWER(I23, 2) -> 0.23005724
A24: 2017 | B24: 10 | C24: 175.3 | D24: =C24-$C$27 -> 7.8083333 | E24: =ABS(D24) -> 7.8083333 | F24: =POWER(E24, 2) -> 60.970069 | G24: =C24/C23*100 -> 101.27094 | H24: =G24-$G$27 -> 0.04670669 | I24: =ABS(H24:H34) -> 0.04670669 | J24: =POWER(I24, 2) -> 0.0021815149
A25: 2018 | B25: 11 | C25: 177.5 | D25: =C25-$C$27 -> 10.008333 | E25: =ABS(D25) -> 10.008333 | F25: =POWER(E25, 2) -> 100.16674 | G25: =C25/C24*100 -> 101.25499 | H25: =G25-$G$27 -> 0.030756481 | I25: =ABS(H25:H35) -> 0.030756481 | J25: =POWER(I25, 2) -> 0.0009459611
A26: 2019 | B26: 12 | C26: 180.4 | D26: =C26-$C$27 -> 12.908333 | E26: =ABS(D26) -> 12.908333 | F26: =POWER(E26, 2) -> 166.62507 | G26: =C26/C25*100 -> 101.6338 | H26: =G26-$G$27 -> 0.40956785 | I26: =ABS(H26:H36) -> 0.40956785 | J26: =POWER(I26, 2) -> 0.16774583
A27: Среднее значение | B27: 13 | C27: =AVERAGE(C15:C26) -> 167.49167 | D27: - | E27: - | F27: - | G27: =POWER(PRODUCT(G16:G26), 1/COUNTA(G16:G26)) -> 101.22423 | H27: - | I27: - | J27: -
A29: Источник: расчеты автора на основе данных ЦДУ ТЭК
A32: Расчетные значения подоле скважин, дающих продукцию, %
A34: Год | C34: Фонд скважин | D34: Х-Хср | E34: |Х-Хср| | F34: (Х-Хср)2 | G34: Сравнение с предущим периодом, % | H34: Х1-Хср | I34: |Х1-Хср| | J34: (Х1-Хср)2
A35: А | B35: Б | C35: В | D35: 1 | E35: 2 | F35: 3 | G35: 4 | H35: 5 | I35: 6 | J35: 7
A36: 2008 | B36: 1 | C36: {=TRANSPOSE(C6:N6)} -> 0.841 | D36: =C36-$C$48 -> -0.018333333 | E36: =ABS(D36) -> 0.018333333 | F36: =POWER(E36, 2) -> 0.00033611111 | G36: - | H36: - | I36: - | J36: -
A37: 2009 | B37: 2 | C37: 0.837 | D37: =C37-$C$48 -> -0.022333333 | E37: =ABS(D37) -> 0.022333333 | F37: =POWER(E37, 2) -> 0.00049877778 | G37: =C37/C36*100 -> 99.524376 | H37: =G37-$G$48 -> -0.66833026 | I37: =ABS(H37:H47) -> 0.66833026 | J37: =POWER(I37, 2) -> 0.44666534
A38: 2010 | B38: 3 | C38: 0.847 | D38: =C38-$C$48 -> -0.012333333 | E38: =ABS(D38) -> 0.012333333 | F38: =POWER(E38, 2) -> 0.00015211111 | G38: =C38/C37*100 -> 101.19474 | H38: =G38-$G$48 -> 1.0020371 | I38: =ABS(H38:H48) -> 1.0020371 | J38: =POWER(I38, 2) -> 1.0040784
A39: 2011 | B39: 4 | C39: 0.853 | D39: =C39-$C$48 -> -0.0063333333 | E39: =ABS(D39) -> 0.0063333333 | F39: =POWER(E39, 2) -> 4.0111111e-05 | G39: =C39/C38*100 -> 100.70838 | H39: =G39-$G$48 -> 0.51567652 | I39: =ABS(H39:H49) -> 0.51567652 | J39: =POWER(I39, 2) -> 0.26592228
A40: 2012 | B40: 5 | C40: 0.855 | D40: =C40-$C$48 -> -0.0043333333 | E40: =ABS(D40) -> 0.0043333333 | F40: =POWER(E40, 2) -> 1.8777778e-05 | G40: =C40/C39*100 -> 100.23447 | H40: =G40-$G$48 -> 0.041760585 | I40: =ABS(H40:H50) -> 0.041760585 | J40: =POWER(I40, 2) -> 0.0017439465
A41: 2013 | B41: 6 | C41: 0.868 | D41: =C41-$C$48 -> 0.0086666667 | E41: =ABS(D41) -> 0.0086666667 | F41: =POWER(E41, 2) -> 7.5111111e-05 | G41: =C41/C40*100 -> 101.52047 | H41: =G41-$G$48 -> 1.3277618 | I41: =ABS(H41:H51) -> 1.3277618 | J41: =POWER(I41, 2) -> 1.7629515
A42: 2014 | B42: 7 | C42: 0.869 | D42: =C42-$C$48 -> 0.0096666667 | E42: =ABS(D42) -> 0.0096666667 | F42: =POWER(E42, 2) -> 9.3444444e-05 | G42: =C42/C41*100 -> 100.11521 | H42: =G42-$G$48 -> -0.07749863 | I42: =ABS(H42:H52) -> 0.07749863 | J42: =POWER(I42, 2) -> 0.0060060377
A43: 2015 | B43: 8 | C43: 0.874 | D43: =C43-$C$48 -> 0.014666667 | E43: =ABS(D43) -> 0.014666667 | F43: =POWER(E43, 2) -> 0.00021511111 | G43: =C43/C42*100 -> 100.57537 | H43: =G43-$G$48 -> 0.38266799 | I43: =ABS(H43:H53) -> 0.38266799 | J43: =POWER(I43, 2) -> 0.14643479
A44: 2016 | B44: 9 | C44: 0.875 | D44: =C44-$C$48 -> 0.015666667 | E44: =ABS(D44) -> 0.015666667 | F44: =POWER(E44, 2) -> 0.00024544444 | G44: =C44/C43*100 -> 100.11442 | H44: =G44-$G$48 -> -0.078289528 | I44: =ABS(H44:H54) -> 0.078289528 | J44: =POWER(I44, 2) -> 0.0061292501
A45: 2017 | B45: 10 | C45: 0.86 | D45: =C45-$C$48 -> 0.00066666667 | E45: =ABS(D45) -> 0.00066666667 | F45: =POWER(E45, 2) -> 4.4444444e-07 | G45: =C45/C44*100 -> 98.285714 | H45: =G45-$G$48 -> -1.9069917 | I45: =ABS(H45:H55) -> 1.9069917 | J45: =POWER(I45, 2) -> 3.6366174
A46: 2018 | B46: 11 | C46: 0.874 | D46: =C46-$C$48 -> 0.014666667 | E46: =ABS(D46) -> 0.014666667 | F46: =POWER(E46, 2) -> 0.00021511111 | G46: =C46/C45*100 -> 101.62791 | H46: =G46-$G$48 -> 1.435201 | I46: =ABS(H46:H56) -> 1.435201 | J46: =POWER(I46, 2) -> 2.0598018
A47: 2019 | B47: 12 | C47: 0.859 | D47: =C47-$C$48 -> -0.00033333333 | E47: =ABS(D47) -> 0.00033333333 | F47: =POWER(E47, 2) -> 1.1111111e-07 | G47: =C47/C46*100 -> 98.283753 | H47: =G47-$G$48 -> -1.9089531 | I47: =ABS(H47:H57) -> 1.9089531 | J47: =POWER(I47, 2) -> 3.6441021
A48: Среднее значение | B48: 13 | C48: =AVERAGE(C36:C47) -> 0.85933333 | D48: - | E48: - | F48: - | G48: =POWER(PRODUCT(G37:G47), 1/COUNTA(G37:G47)) -> 100.19271 | H48: - | I48: - | J48: -
A50: Изменение фонда скважин по сравнению с предыдущим периодом, %
...

Sheet 1.5
A1: Запасы углеводородов (доказанные) на 30.12.2019 и 30.12.2020, млн. б.н.э
A3: Наименование компании | C3: Запасы углеводородов на 30.12.2020 | D3: Запасы углеводородов на 30.12.2019
A4: А | B4: Б | C4: 1 | D4: 1
A5: Всего | B5: 1 | C5: =SUM(C6:C15) -> 248633.7 | D5: =SUM(D6:D15) -> 246839.9
A6: ПАО "ЛУКОЙЛ" | B6: 2 | C6: 15400 | D6: 15800
A7: ПАО "ГАЗПРОМ" | B7: 3 | C7: 178510 | D7: 177100
A8: ПАО НК "РОССНЕФТЬ" | B8: 4 | C8: 3489 | D8: 3935
A9: ПАО "ТАТНЕФТЬ" | B9: 5 | C9: 8728.4 | D9: 9156
A10: ПАО "НОВАТЭК" | B10: 6 | C10: 16366 | D10: 16265
A11: ПАО АНК "БАШНЕФТЬ" | B11: 7 | C11: 13046 | D11: 13026
A12: ПАО НК "РУССНЕФТЬ" | B12: 8 | C12: 7687.3 | D12: 7687.3
A13: ПАО "НГК СЛАВНЕФТЬ" | B13: 9 | C13: 228.3 | D13: 234
A14: ПАО "ЛУКОЙЛ-ПЕРМЬ" | B14: 10 | C14: 4968.3 | D14: 3400
A15: ООО "ЛУКОЙЛ-Калининградморнефть" | B15: 11 | C15: 210.4 | D15: 236.6
A18: Источники:
A19: Оценка запасов ПАО "ЛУКОЙЛ" за 2020/2019 год | B19: https://lukoil.ru/PressCenter/Pressreleases/Pressrelease/lukoil-zavershil-otsenku-zapasov-na-konets-2020-goda | D19: https://lukoil.ru/PressCenter/Pressreleases/Pressrelease/lukoil-zavershil-otsenku-zapasov-na-konets-2019-goda
A20: Годовой отчет ПАО "ГАЗПРОМ" за 2020/2019 год | B20: https://www.gazprom.ru/f/posts/05/118974/2020-mngmnt-report-ru.pdf | D20: https://www.gazprom.ru/f/posts/77/885487/2019-mgt-report-ru.pdf
A21: Отчет в области устойчивого развития 2020/2019 ПАО НК "РОССНЕФТЬ" | B21: https://www.rosneft.ru/upload/site1/document_file/Rosneft_CSR2020_RUS.pdf | D21: https://www.rosneft.ru/upload/site1/document_file/Rosneft_CSR2020_RUS.pdf
A22: Результаты аудита запасов нефти и газа ПАО "ТАТНЕФТЬ" за 2020/2019 | B22: https://www.tatneft.ru/news/4562 | D22: https://www.tatneft.ru/news/62?ysclid=mp6yfb06id253450951
A23: Восполнение запасов ПАО «НОВАТЭК» в 2020/2019 году | B23: https://www.novatek.ru/ru/press/releases/?id_4=4222 | D23: https://www.novatek.ru/ru/press/releases/archive/index.php?id_4=3692
A24: Годовой отчет за 2020/2019 год "БАШНЕФТЬ" | B24: https://www.sinref.ru/000_uchebniki/04600_raznie_11/170_976_Bashneft_godovoi_2020_04600_raznie_13/003.htm | D24: https://bashneft.rosneft.ru/files/iblock/092/Годовой_отчет_2019.pdf
A25: Годовой отчет за 2020 год "РУССНЕФТЬ"/ Статья о запасах углеводородов на 2019 год | B25: https://russneft.ru/upload/iblock/cf3/3bx47h8gvwu083xjof054q39eapojq2f.pdf | D25: https://earchive.tpu.ru/bitstream/11683/68703/1/conference_tpu-2021-C11_V2_p478-479.pdf
A26: Годовой отчет ПАО "НГК СЛАВНЕФТЬ" за 2020/2019 год | B26: https://www.sinref.ru/000_uchebniki/04600_raznie_13/593_Mosenergo-godovoi-za-2021-god/006.htm | D26: https://vk.com/away.php?to=https%3A%2F%2Fwww.e-disclosure.ru%2Fportal%2FFileLoad.ashx%3FFileid%3D1535955&utf=1
A27: Анализ ООО "ЛУКОЙЛ-Калининградморнефть" за 2020 год | B27: https://neftegaz.ru/news/dobycha/659761-lukoyl-kaliningradmorneft-v-2020-g-snizil-dobychu-nefti-na-10/ | D27: https://vk.com/away.php?to=https%3A%2F%2Fneftegaz.ru%2Fnews%2Fdobycha%2F522700-lukoyl-kaliningradmorneft-v-2019-g-uvelichil-dobychu-nefti-na-shelfe-baltiki-na-3-1%2F&utf=1
A28: Годовой отчет ПАО "ЛУКОЙЛ-ПЕРМЬ" за 2020/2019 год | B28: https://permneft-portal.ru/ | D28: https://www.interfax-russia.ru/volga/news/lukoyl-perm-v-2019g-planiruet-uvelichit-neftedobychu-pochti-na-2-gaza-sohranit-na-urovne-2018
A31: Запасы углеводородов на 30.12.2020 и 30.12.2019 по сравнению с ПАО "ЛУКОЙЛ" в абсолютном выражении, млн. б.н.э
A33: Наименование компании | C33: Запасы углеводородов на 30.12.2020 | D33: Запасы углеводородов на 30.12.2019
A34: А | B34: Б | C34: 1 | D34: 2
A35: {=A7:A15} -> ПАО "ГАЗПРОМ" | B35: 1 | C35: =C7-$C$6 -> 163110 | D35: =D7-$D$6 -> 161300
A36: ПАО НК "РОССНЕФТЬ" | B36: 2 | C36: =C8-$C$6 -> -11911 | D36: =D8-$D$6 -> -11865
A37: ПАО "ТАТНЕФТЬ" | B37: 3 | C37: =C9-$C$6 -> -6671.6 | D37: =D9-$D$6 -> -6644
A38: ПАО "НОВАТЭК" | B38: 4 | C38: =C10-$C$6 -> 966 | D38: =D10-$D$6 -> 465
A39: ПАО АНК "БАШНЕФТЬ" | B39: 5 | C39: =C11-$C$6 -> -2354 | D39: =D11-$D$6 -> -2774
A40: ПАО НК "РУССНЕФТЬ" | B40: 6 | C40: =C12-$C$6 -> -7712.7 | D40: =D12-$D$6 -> -8112.7
A41: ПАО "НГК СЛАВНЕФТЬ" | B41: 7 | C41: =C13-$C$6 -> -15171.7 | D41: =D13-$D$6 -> -15566
A42: ПАО "ЛУКОЙЛ-ПЕРМЬ" | B42: 8 | C42: =C14-$C$6 -> -10431.7 | D42: =D14-$D$6 -> -12400
A43: ООО "ЛУКОЙЛ-Калининградморнефть" | B43: 9 | C43: =C15-$C$6 -> -15189.6 | D43: =D15-$D$6 -> -15563.4
A45: Источник: расчет автора на основе данных отчетов компаний
A48: Запасы углеводородов на 30.12.2020 и 30.12.2019 по сравнению с ПАО "ЛУКОЙЛ", %
A50: Наименование компании | C50: Запасы углеводородов на 30.12.2020 | D50: Запасы углеводородов на 30.12.2019
...

Sheet 1.6
A1: Международное сопоставление по суммарным уровням добычи нефти, млн.т
A3: Наименование страны | C3: 2008 | D3: 2009 | E3: 2010 | F3: 2011 | G3: 2012 | H3: 2013 | I3: 2014 | J3: 2015 | K3: 2016 | L3: 2017 | M3: 2018 | N3: 2019 | O3: Среднее значение добычи нефти | P3: Xмин | Q3: Хмакс | R3: Размах враиации, R | S3: Медиана, Ме | T3: Q1 | U3: Q3 | V3: Межквартильный размах, IQR | W3: Среднее линйеное отклонение, L | X3: Дисперсия | Y3: Среднеквадратическое отклонение, СКО | Z3: Коэффициент осциляции (VR), % | AA3: Коэффициент линейного отклонения (VL), % | AB3: Коэффициент вариации (V), %
A4: А | B4: Б | C4: 1 | D4: 2 | E4: 3 | F4: 4 | G4: 5 | H4: 6 | I4: 7 | J4: 8 | K4: 9 | L4: 10 | M4: 11 | N4: 12 | O4: 13 | P4: 14 | Q4: 15 | R4: 16 | S4: 17 | T4: 18 | U4: 19 | V4: 20 | W4: 21 | X4: 22 | Y4: 23 | Z4: 24 | AA4: 25 | AB4: 26
A5: Всего добыча по миру | B5: 1 | C5: 3994 | D5: 3994 | E5: 3992 | F5: 3979 | G5: 4098 | H5: 4117 | I5: 4213 | J5: 4316 | K5: 4375 | L5: 4377 | M5: 4482 | N5: н/д | O5: =AVERAGE(C5:M5) -> 4176.0909 | P5: =QUARTILE(C5:M5,0) -> 3979 | Q5: =QUARTILE(C5:M5, 4) -> 4482 | R5: =Q5-P5 -> 503 | S5: =QUARTILE(C5:M5,2) -> 4117 | T5: =QUARTILE(C5:M5,1) -> 3994 | U5: =QUARTILE(C5:M5,3) -> 4345.5 | V5: Me= 4117,0 (Q1-Q3: 3994,0-4345,5) | W5: =SUM(E24:E34)/COUNTA(E24:E34) -> 160.46281 | X5: =SUM(F66:F76)/COUNTA(F66:F76) -> 75.251736 | Y5: =SQRT(X5) -> 8.6747758 | Z5: =R5/O5*100 -> 12.044757 | AA5: =W5/O5*100 -> 3.8424166 | AB5: =Y5/O5*100 -> 0.20772478
A6: Российская Федерация | B6: 2 | C6: 488 | D6: 494 | E6: 506 | F6: 512 | G6: 519 | H6: 522 | I6: 526 | J6: 535 | K6: 548 | L6: 547 | M6: 556 | O6: =AVERAGE(C6:M6) -> 523 | P6: =QUARTILE(C6:M6,0) -> 488 | Q6: =QUARTILE(C6:M6, 4) -> 556 | R6: =Q6-P6 -> 68 | S6: =QUARTILE(C6:M6,2) -> 522 | T6: =QUARTILE(C6:M6,1) -> 509 | U6: =QUARTILE(C6:M6,3) -> 541 | V6: Me= 522,0 (Q1-Q3: 509,0-541,0) | W6: =SUM(E45:E55)/COUNTA(E45:E55) -> 17.636364 | X6: =SUM(F45:F55)/COUNTA(F45:F55) -> 448.72727 | Y6: =SQRT(X6) -> 21.183184 | Z6: =R6/O6*100 -> 13.001912 | AA6: =W6/O6*100 -> 3.3721537 | AB6: =Y6/O6*100 -> 4.0503219
A7: Соединенное королевство (Великобритания) | B7: 3 | C7: 65.5 | D7: 62.8 | E7: 63 | F7: 52 | G7: 44.6 | H7: 40.7 | I7: 40 | J7: 45.3 | K7: 47.4 | L7: 46.5 | M7: 50.9 | O7: =AVERAGE(C7:M7) -> 50.790909 | P7: =QUARTILE(C7:M7,0) -> 40 | Q7: =QUARTILE(C7:M7, 4) -> 65.5 | R7: =Q7-P7 -> 25.5 | S7: =QUARTILE(C7:M7,2) -> 47.4 | T7: =QUARTILE(C7:M7,1) -> 44.95 | U7: =QUARTILE(C7:M7,3) -> 57.4 | V7: Me= 47,4 (Q1-Q3: 45,0-57,4) | W7: =SUM(E66:E76)/COUNTA(E66:E76) -> 7.3173554 | X7: =SUM(F286:F297)/COUNTA(C7:N7) -> 690.94901 | Y7: =SQRT(X7) -> 26.285909 | Z7: =R7/O7*100 -> 50.205835 | AA7: =W7/O7*100 -> 14.406821 | AB7: =Y7/O7*100 -> 51.753177
A8: Украина | B8: 4 | C8: 4.3 | D8: 4 | E8: 3.6 | F8: 3.4 | G8: 3.3 | H8: 3.1 | I8: 2.7 | J8: 2.6 | K8: 2.3 | L8: 2.2 | M8: 2.3 | O8: =AVERAGE(C8:M8) -> 3.0727273 | P8: =QUARTILE(C8:M8,0) -> 2.2 | Q8: =QUARTILE(C8:M8, 4) -> 4.3 | R8: =Q8-P8 -> 2.1 | S8: =QUARTILE(C8:M8,2) -> 3.1 | T8: =QUARTILE(C8:M8,1) -> 2.45 | U8: =QUARTILE(C8:M8,3) -> 3.5 | V8: Me= 3,1 (Q1-Q3: 2,5-3,5) | W8: =SUM(E87:E97)/COUNTA(E87:E97) -> 47.718182 | X8: =SUM(F306:F317)/COUNTA(C8:N8) -> 212.12725 | Y8: =SQRT(X8) -> 14.564589 | Z8: =R8/O8*100 -> 68.343195 | AA8: =W8/O8*100 -> 1552.9586 | AB8: =Y8/O8*100 -> 473.9955
A9: Объединенный Арабские Эмираты | B9: 5 | C9: 124 | D9: 108 | E9: 134 | F9: 144 | G9: 148 | H9: 154 | I9: 168 | J9: 178 | K9: 184 | L9: 176 | M9: 179 | O9: =AVERAGE(C9:M9) -> 154.27273 | P9: =QUARTILE(C9:M9,0) -> 108 | Q9: =QUARTILE(C9:M9, 4) -> 184 | R9: =Q9-P9 -> 76 | S9: =QUARTILE(C9:M9,2) -> 154 | T9: =QUARTILE(C9:M9,1) -> 139 | U9: =QUARTILE(C9:M9,3) -> 177 | V9: Me= 154,0 (Q1-Q3: 139,0-177,0) | W9: =SUM(E108:E118)/COUNTA(E108:E118) -> 20.661157 | X9: =SUM(F108:F118)/COUNTA(F108:F118) -> 575.65289 | Y9: =SQRT(X9) -> 23.992768 | Z9: =R9/O9*100 -> 49.263406 | AA9: =W9/O9*100 -> 13.392618 | AB9: =Y9/O9*100 -> 15.552177
A10: Саудовская Аравия | B10: 6 | C10: 460 | D10: 408 | E10: 461 | F10: 520 | G10: 547 | H10: 536 | I10: 541 | J10: 565 | K10: 584 | L10: 556 | M10: 575 | O10: =AVERAGE(C10:M10) -> 523 | P10: =QUARTILE(C10:M10,0) -> 408 | Q10: =QUARTILE(C10:M10, 4) -> 584 | R10: =Q10-P10 -> 176 | S10: =QUARTILE(C10:M10,2) -> 541 | T10: =QUARTILE(C10:M10,1) -> 490.5 | U10: =QUARTILE(C10:M10,3) -> 560.5 | V10: Me= 541,0 (Q1-Q3: 490,5-560,5) | W10: =SUM(E129:E139)/COUNTA(E129:E139) -> 44.181818 | X10: =SUM(F129:F139)/COUNTA(F129:F139) -> 2854 | Y10: =SQRT(X10) -> 53.422842 | Z10: =R10/O10*100 -> 33.652008 | AA10: =W10/O10*100 -> 8.4477664 | AB10: =Y10/O10*100 -> 10.214692
A11: США | B11: 7 | C11: 245 | D11: 264 | E11: 330 | F11: 343 | G11: 388 | H11: 448 | I11: 524 | J11: 560 | K11: 538 | L11: 569 | M11: 666 | O11: =AVERAGE(C11:M11) -> 443.18182 | P11: =QUARTILE(C11:M11,0) -> 245 | Q11: =QUARTILE(C11:M11, 4) -> 666 | R11: =Q11-P11 -> 421 | S11: =QUARTILE(C11:M11,2) -> 448 | T11: =QUARTILE(C11:M11,1) -> 336.5 | U11: =QUARTILE(C11:M11,3) -> 549 | V11: Me= 448,0 (Q1-Q3: 336,5-549,0) | W11: =SUM(E150:E160)/COUNTA(E150:E160) -> 117.43802 | X11: =SUM(F150:F160)/COUNTA(F150:F160) -> 17449.421 | Y11: =SQRT(X11) -> 132.09626 | Z11: =R11/O11*100 -> 94.994872 | AA11: =W11/O11*100 -> 26.498834 | AB11: =Y11/O11*100 -> 29.806335
A12: Китай | B12: 8 | C12: 195 | D12: 190 | E12: 203 | F12: 203 | G12: 208 | H12: 210 | I12: 212 | J12: 215 | K12: 200 | L12: 192 | M12: 188 | O12: =AVERAGE(C12:M12) -> 201.45455 | P12: =QUARTILE(C12:M12,0) -> 188 | Q12: =QUARTILE(C12:M12, 4) -> 215 | R12: =Q12-P12 -> 27 | S12: =QUARTILE(C12:M12,2) -> 203 | T12: =QUARTILE(C12:M12,1) -> 193.5 | U12: =QUARTILE(C12:M12,3) -> 209 | V12: Me= 203,0 (Q1-Q3: 193,5-209,0) | W12: =SUM(E171:E181)/COUNTA(E171:E181) -> 7.6859504 | X12: =SUM(F171:F181)/COUNTA(F171:F181) -> 78.247934 | Y12: =SQRT(X12) -> 8.8457862 | Z12: =R12/O12*100 -> 13.402527 | AA12: =W12/O12*100 -> 3.8152281 | AB12: =Y12/O12*100 -> 4.3909589
A13: Норвегия | B13: 9 | C13: 106 | D13: 99.2 | E13: 99.6 | F13: 94.2 | G13: 87.6 | H13: 83.5 | I13: 84.3 | J13: 87.8 | K13: 90.2 | L13: 89 | M13: 83.6 | O13: =AVERAGE(C13:M13) -> 91.363636 | P13: =QUARTILE(C13:M13,0) -> 83.5 | Q13: =QUARTILE(C13:M13, 4) -> 106 | R13: =Q13-P13 -> 22.5 | S13: =QUARTILE(C13:M13,2) -> 89 | T13: =QUARTILE(C13:M13,1) -> 85.95 | U13: =QUARTILE(C13:M13,3) -> 96.7 | V13: Me= 89,0 (Q1-Q3: 86,0-96,7) | W13: =SUM(E192:E202)/COUNTA(E192:E202) -> 6.0991736 | X13: =SUM(F192:F202)/COUNTA(F192:F202) -> 50.66595 | Y13: =SQRT(X13) -> 7.1180019 | Z13: =R13/O13*100 -> 24.626866 | AA13: =W13/O13*100 -> 6.6757123 | AB13: =Y13/O13*100 -> 7.7908478
A14: Ирак | B14: 10 | C14: 100 | D14: 113 | E14: 117 | F14: 134 | G14: 146 | H14: 148 | I14: 154 | J14: 173 | K14: 222 | L14: 226 | M14: 231 | O14: =AVERAGE(C14:M14) -> 160.36364 | P14: =QUARTILE(C14:M14,0) -> 100 | Q14: =QUARTILE(C14:M14, 4) -> 231 | R14: =Q14-P14 -> 131 | S14: =QUARTILE(C14:M14,2) -> 148 | T14: =QUARTILE(C14:M14,1) -> 125.5 | U14: =QUARTILE(C14:M14,3) -> 197.5 | V14: Me= 148,0 (Q1-Q3: 125,5-197,5) | W14: =SUM(E213:E223)/COUNTA(E213:E223) -> 38.280992 | X14: =SUM(F213:F223)/COUNTA(F213:F223) -> 2010.7769 | Y14: =SQRT(X14) -> 44.841687 | Z14: =R14/O14*100 -> 81.689342 | AA14: =W14/O14*100 -> 23.871367 | AB14: =Y14/O14*100 -> 27.962503
A15: Кувейт | B15: 11 | C15: 135 | D15: 114 | E15: 123 | F15: 141 | G15: 158 | H15: 155 | I15: 152 | J15: 152 | K15: 158 | L15: 145.9 | M15: 147.7 | O15: =AVERAGE(C15:M15) -> 143.78182 | P15: =QUARTILE(C15:M15,0) -> 114 | Q15: =QUARTILE(C15:M15, 4) -> 158 | R15: =Q15-P15 -> 44 | S15: =QUARTILE(C15:M15,2) -> 147.7 | T15: =QUARTILE(C15:M15,1) -> 138 | U15: =QUARTILE(C15:M15,3) -> 153.5 | V15: Me= 147,7 (Q1-Q3: 138,0-153,5) | W15: =SUM(E234:E244)/COUNTA(E234:E244) -> 11.295868 | X15: =SUM(F234:F244)/COUNTA(F234:F244) -> 189.88876 | Y15: =SQRT(X15) -> 13.780013 | Z15: =R15/O15*100 -> 30.601922 | AA15: =W15/O15*100 -> 7.856256 | AB15: =Y15/O15*100 -> 9.5839747
A17: Источник: данные Росстата
A20: Расчетные данные по суммарной добычи нефти (всего), по годам, млн.т
A22: Год | C22: Добыча нефти | D22: Х-Хср | E22: |Х-Хср| | F22: (Х-Хср)2 | G22: Среднее изменение добычи нефти, % | H22: Х-Хср | I22: |Х-Хср| | J22: (Х-Хср)2
A23: А | B23: Б | C23: В | D23: 1 | E23: 2 | F23: 3 | G23: 4 | H23: 5 | I23: 6 | J23: 7
A24: 2008 | B24: 1 | C24: {=TRANSPOSE(C5:M5)} -> 3994 | D24: =C24-$C$36 -> -182.09091 | E24: =ABS(D24) -> 182.09091 | F24: =POWER(E24,2) -> 33157.099 | G24: - | H24: - | I24: - | J24: -
A25: 2009 | B25: 2 | C25: 3994 | D25: =C25-$C$36 -> -182.09091 | E25: =ABS(D25) -> 182.09091 | F25: =POWER(E25,2) -> 33157.099 | G25: =C25/C24*100 -> 100 | H25: =G25-$G$36 -> -1.1594313 | I25: =ABS(H25) -> 1.1594313 | J25: =POWER(I25,2) -> 1.3442809
A26: 2010 | B26: 3 | C26: 3992 | D26: =C26-$C$36 -> -184.09091 | E26: =ABS(D26) -> 184.09091 | F26: =POWER(E26,2) -> 33889.463 | G26: =C26/C25*100 -> 99.949925 | H26: =G26-$G$36 -> -1.2095064 | I26: =ABS(H26) -> 1.2095064 | J26: =POWER(I26,2) -> 1.4629058
A27: 2011 | B27: 4 | C27: 3979 | D27: =C27-$C$36 -> -197.09091 | E27: =ABS(D27) -> 197.09091 | F27: =POWER(E27,2) -> 38844.826 | G27: =C27/C26*100 -> 99.674349 | H27: =G27-$G$36 -> -1.4850826 | I27: =ABS(H27) -> 1.4850826 | J27: =POWER(I27,2) -> 2.2054703
A28: 2012 | B28: 5 | C28: 4098 | D28: =C28-$C$36 -> -78.090909 | E28: =ABS(D28) -> 78.090909 | F28: =POWER(E28,2) -> 6098.1901 | G28: =C28/C27*100 -> 102.9907 | H28: =G28-$G$36 -> 1.8312699 | I28: =ABS(H28) -> 1.8312699 | J28: =POWER(I28,2) -> 3.3535494
A29: 2013 | B29: 6 | C29: 4117 | D29: =C29-$C$36 -> -59.090909 | E29: =ABS(D29) -> 59.090909 | F29: =POWER(E29,2) -> 3491.7355 | G29: =C29/C28*100 -> 100.46364 | H29: =G29-$G$36 -> -0.6957905 | I29: =ABS(H29) -> 0.6957905 | J29: =POWER(I29,2) -> 0.48412442
A30: 2014 | B30: 7 | C30: 4213 | D30: =C30-$C$36 -> 36.909091 | E30: =ABS(D30) -> 36.909091 | F30: =POWER(E30,2) -> 1362.281 | G30: =C30/C29*100 -> 102.33179 | H30: =G30-$G$36 -> 1.1723637 | I30: =ABS(H30) -> 1.1723637 | J30: =POWER(I30,2) -> 1.3744366
A31: 2015 | B31: 8 | C31: 4316 | D31: =C31-$C$36 -> 139.90909 | E31: =ABS(D31) -> 139.90909 | F31: =POWER(E31,2) -> 19574.554 | G31: =C31/C30*100 -> 102.44481 | H31: =G31-$G$36 -> 1.2853824 | I31: =ABS(H31) -> 1.2853824 | J31: =POWER(I31,2) -> 1.6522078
A32: 2016 | B32: 9 | C32: 4375 | D32: =C32-$C$36 -> 198.90909 | E32: =ABS(D32) -> 198.90909 | F32: =POWER(E32,2) -> 39564.826 | G32: =C32/C31*100 -> 101.36701 | H32: =G32-$G$36 -> 0.20757518 | I32: =ABS(H32) -> 0.20757518 | J32: =POWER(I32,2) -> 0.043087457
A33: 2017 | B33: 10 | C33: 4377 | D33: =C33-$C$36 -> 200.90909 | E33: =ABS(D33) -> 200.90909 | F33: =POWER(E33,2) -> 40364.463 | G33: =C33/C32*100 -> 100.04571 | H33: =G33-$G$36 -> -1.113717 | I33: =ABS(H33) -> 1.113717 | J33: =POWER(I33,2) -> 1.2403656
A34: 2018 | B34: 11 | C34: 4482 | D34: =C34-$C$36 -> 305.90909 | E34: =ABS(D34) -> 305.90909 | F34: =POWER(E34,2) -> 93580.372 | G34: =C34/C33*100 -> 102.3989 | H34: =G34-$G$36 -> 1.2394721 | I34: =ABS(H34) -> 1.2394721 | J34: =POWER(I34,2) -> 1.536291
A35: 2019 | B35: 12 | C35: - | D35: - | E35: - | F35: - | G35: - | H35: - | I35: - | J35: -
A36: Среднее значение | B36: 13 | C36: =AVERAGE(C24:C34) -> 4176.0909 | D36: - | E36: - | F36: - | G36: =POWER(PRODUCT(G25:G34), 1/COUNTA(G25:G34)) -> 101.15943 | H36: - | I36: - | J36: -
A38: Источник: составлено автром на основе данных Росстата
A41: Расчетные данные по суммарной добычи нефти в Российской Федерации, по годам, млн.т
A43: Год | C43: Добыча нефти | D43: Х-Хср | E43: |Х-Хср| | F43: (Х-Хср)2 | G43: Среднее изменение добычи нефти, % | H43: Х-Хср | I43: |Х-Хср| | J43: (Х-Хср)2
A44: А | B44: Б | C44: В | D44: 1 | E44: 2 | F44: 3 | G44: 4 | H44: 5 | I44: 6 | J44: 7
A45: 2008 | B45: 1 | C45: {=TRANSPOSE(C6:M6)} -> 488 | D45: =C45-$C$57 -> -35 | E45: =ABS(D45) -> 35 | F45: =POWER(E45,2) -> 1225 | G45: - | H45: - | I45: - | J45: -
A46: 2009 | B46: 2 | C46: 494 | D46: =C46-$C$57 -> -29 | E46: =ABS(D46) -> 29 | F46: =POWER(E46,2) -> 841 | G46: =C46/C45*100 -> 101.22951 | H46: =G46-$G$57 -> -0.083566787 | I46: =ABS(H46) -> 0.083566787 | J46: =POWER(I46,2) -> 0.0069834079
A47: 2010 | B47: 3 | C47: 506 | D47: =C47-$C$57 -> -17 | E47: =ABS(D47) -> 17 | F47: =POWER(E47,2) -> 289 | G47: =C47/C46*100 -> 102.42915 | H47: =G47-$G$57 -> 1.1160748 | I47: =ABS(H47) -> 1.1160748 | J47: =POWER(I47,2) -> 1.245623
A48: 2011 | B48: 4 | C48: 512 | D48: =C48-$C$57 -> -11 | E48: =ABS(D48) -> 11 | F48: =POWER(E48,2) -> 121 | G48: =C48/C47*100 -> 101.18577 | H48: =G48-$G$57 -> -0.12730423 | I48: =ABS(H48) -> 0.12730423 | J48: =POWER(I48,2) -> 0.016206368
A49: 2012 | B49: 5 | C49: 519 | D49: =C49-$C$57 -> -4 | E49: =ABS(D49) -> 4 | F49: =POWER(E49,2) -> 16 | G49: =C49/C48*100 -> 101.36719 | H49: =G49-$G$57 -> 0.054112516 | I49: =ABS(H49) -> 0.054112516 | J49: =POWER(I49,2) -> 0.0029281644
...

Sheet 1.7
